Workbook

Sheet CUSTOMER BUDGET
N1: Union Chief
A2: M5 Services
A3: LABOR COST ESTIMATE 2026 | R3: 45901 | S3: 45931 | T3: 45962 | U3: 45992
A4: Union Chief || @ Building @ Customer
B6: 46023 | C6: Feburary 2026 | D6: 46082 | E6: 46113 | F6: 46143 | G6: 46174 | H6: 46204 | I6: 46235 | J6: 45901 | K6: 45931 | L6: 45962 | M6: 45992 | N6: TOTALS | P6: 44805 | Q6: 45170 | R6: 45352 | S6: 45536
A7: Hours Per EE Per Month | B7: ='INTERNAL BUDGET'!I4 -> 176 | C7: ='INTERNAL BUDGET'!J4 -> 160 | D7: ='INTERNAL BUDGET'!K4 -> 176 | E7: ='INTERNAL BUDGET'!L4 -> 176 | F7: ='INTERNAL BUDGET'!M4 -> 168 | G7: ='INTERNAL BUDGET'!N4 -> 176 | H7: ='INTERNAL BUDGET'!O4 -> 184 | I7: ='INTERNAL BUDGET'!P4 -> 168 | ... M7: ='INTERNAL BUDGET'!T4 -> 184 | N7: =SUM(B7:M7) -> 2088
T8: FTE #
A9: Union Engineer | B9: ='INTERNAL BUDGET'!I5 -> 93.35 | C9: ='INTERNAL BUDGET'!J5 -> 93.35 | D9: ='INTERNAL BUDGET'!K5 -> 93.35 | E9: ='INTERNAL BUDGET'!L5 -> 93.35 | F9: ='INTERNAL BUDGET'!M5 -> 93.35 | G9: ='INTERNAL BUDGET'!N5 -> 93.35 | H9: ='INTERNAL BUDGET'!O5 -> 93.35 | I9: ='INTERNAL BUDGET'!P5 -> 93.35 | ... M9: ='INTERNAL BUDGET'!T5 -> 97.92 | P9: 79.27 | Q9: 82.05 | R9: 84.83 | S9: 88.99 | T9: 1
A10: Straight-time Labor Cost | B10: =SUM(B9*B7) -> 16429.6 | C10: =SUM(C9*C7) -> 14936 | D10: =SUM(D9*D7) -> 16429.6 | E10: =SUM(E9*E7) -> 16429.6 | F10: =SUM(F9*F7) -> 15682.8 | G10: =SUM(G9*G7) -> 16429.6 | H10: =SUM(H9*H7) -> 17176.4 | I10: =SUM(I9*I7) -> 15682.8 | ... M10: =SUM(M9*M7) -> 18017.28 | N10: =SUM(B10:M10) -> 198132.08
A12: Total Straight-time Labor Cost | B12: =SUM(B10) -> 16429.6 | C12: =SUM(C10) -> 14936 | D12: =SUM(D10) -> 16429.6 | E12: =SUM(E10) -> 16429.6 | F12: =SUM(F10) -> 15682.8 | G12: =SUM(G10) -> 16429.6 | H12: =SUM(H10) -> 17176.4 | I12: =SUM(I10) -> 15682.8 | ... M12: =SUM(M10) -> 18017.28 | N12: =SUM(B12:M12) -> 198132.08 | T12: 2
A14: Union Health and Welfare | B14: ='INTERNAL BUDGET'!I23 -> 2680 | C14: ='INTERNAL BUDGET'!J23 -> 2680 | D14: ='INTERNAL BUDGET'!K23 -> 2680 | E14: ='INTERNAL BUDGET'!L23 -> 2680 | F14: ='INTERNAL BUDGET'!M23 -> 2680 | G14: ='INTERNAL BUDGET'!N23 -> 2680 | H14: ='INTERNAL BUDGET'!O23 -> 2680 | I14: ='INTERNAL BUDGET'!P23 -> 2680 | ... M14: ='INTERNAL BUDGET'!T23 -> 2680 | N14: =SUM(B14:M14) -> 32160 | Q14: 2480 | S14: 2480 | T14: 2
A15: Pension | B15: ='INTERNAL BUDGET'!I24 -> 2559.04 | C15: ='INTERNAL BUDGET'!J24 -> 2326.4 | D15: ='INTERNAL BUDGET'!K24 -> 2559.04 | E15: ='INTERNAL BUDGET'!L24 -> 2559.04 | F15: ='INTERNAL BUDGET'!M24 -> 2442.72 | G15: ='INTERNAL BUDGET'!N24 -> 2559.04 | H15: ='INTERNAL BUDGET'!O24 -> 2675.36 | I15: ='INTERNAL BUDGET'!P24 -> 2442.72 | ... M15: ='INTERNAL BUDGET'!T24 -> 2835.44 | N15: =SUM(B15:M15) -> 30972 | Q15: 12.94 | S15: 13.72 | T15: 2
A16: Annuity | B16: ='INTERNAL BUDGET'!I25 -> 369.6 | C16: ='INTERNAL BUDGET'!J25 -> 336 | D16: ='INTERNAL BUDGET'!K25 -> 369.6 | E16: ='INTERNAL BUDGET'!L25 -> 369.6 | F16: ='INTERNAL BUDGET'!M25 -> 352.8 | G16: ='INTERNAL BUDGET'!N25 -> 369.6 | H16: ='INTERNAL BUDGET'!O25 -> 386.4 | I16: ='INTERNAL BUDGET'!P25 -> 352.8 | ... M16: ='INTERNAL BUDGET'!T25 -> 386.4 | N16: =SUM(B16:M16) -> 4384.8 | Q16: 2 | S16: 2.05 | T16: 2
A17: Local 39 Training Fund | B17: ='INTERNAL BUDGET'!I26 -> 1115 | C17: ='INTERNAL BUDGET'!J26 | D17: ='INTERNAL BUDGET'!K26 | E17: ='INTERNAL BUDGET'!L26 | F17: ='INTERNAL BUDGET'!M26 | G17: ='INTERNAL BUDGET'!N26 | H17: ='INTERNAL BUDGET'!O26 | I17: ='INTERNAL BUDGET'!P26 | ... N17: ='INTERNAL BUDGET'!U26 | Q17: 1119 | T17: 2
A18: National Training Fund | B18: ='INTERNAL BUDGET'!I27 -> 104 | C18: ='INTERNAL BUDGET'!J27 | D18: ='INTERNAL BUDGET'!K27 | E18: ='INTERNAL BUDGET'!L27 | F18: ='INTERNAL BUDGET'!M27 | G18: ='INTERNAL BUDGET'!N27 | H18: ='INTERNAL BUDGET'!O27 | I18: ='INTERNAL BUDGET'!P27 | ... N18: ='INTERNAL BUDGET'!U27 | P18: 2023 | S18: 2024
A21: Life/LTD | B21: ='INTERNAL BUDGET'!I44 -> 91.092 | C21: ='INTERNAL BUDGET'!J44 -> 91.092 | D21: ='INTERNAL BUDGET'!K44 -> 91.092 | E21: ='INTERNAL BUDGET'!L44 -> 91.092 | F21: ='INTERNAL BUDGET'!M44 -> 91.092 | G21: ='INTERNAL BUDGET'!N44 -> 91.092 | H21: ='INTERNAL BUDGET'!O44 -> 91.092 | I21: ='INTERNAL BUDGET'!P44 -> 91.092 | ... M21: ='INTERNAL BUDGET'!T44 -> 91.092 | N21: =SUM(B21:M21) -> 1093.104 | P21: 87.27 | S21: 87.27 | T21: 2
A22: Uniforms | B22: ='INTERNAL BUDGET'!I40 -> 157.4973 | C22: ='INTERNAL BUDGET'!J40 -> 157.4973 | D22: ='INTERNAL BUDGET'!K40 -> 157.4973 | E22: ='INTERNAL BUDGET'!L40 -> 157.4973 | F22: ='INTERNAL BUDGET'!M40 -> 157.4973 | G22: ='INTERNAL BUDGET'!N40 -> 157.4973 | H22: ='INTERNAL BUDGET'!O40 -> 157.4973 | I22: ='INTERNAL BUDGET'!P40 -> 157.4973 | ... M22: ='INTERNAL BUDGET'!T40 -> 157.4973 | N22: =SUM(B22:M22) -> 1889.9676 | P22: 100 | S22: 160 | T22: 2
A23: Phone | B23: ='INTERNAL BUDGET'!I41 -> 94.5 | C23: ='INTERNAL BUDGET'!J41 -> 94.5 | D23: ='INTERNAL BUDGET'!K41 -> 94.5 | E23: ='INTERNAL BUDGET'!L41 -> 94.5 | F23: ='INTERNAL BUDGET'!M41 -> 94.5 | G23: ='INTERNAL BUDGET'!N41 -> 94.5 | H23: ='INTERNAL BUDGET'!O41 -> 94.5 | I23: ='INTERNAL BUDGET'!P41 -> 94.5 | ... M23: ='INTERNAL BUDGET'!T41 -> 94.5 | N23: =SUM(B23:M23) -> 1134 | P23: 90 | S23: 90 | T23: 2
A24: Safety, Email, ADP | B24: ='INTERNAL BUDGET'!I48 -> 127 | C24: ='INTERNAL BUDGET'!J48 -> 127 | D24: ='INTERNAL BUDGET'!K48 -> 127 | E24: ='INTERNAL BUDGET'!L48 -> 127 | F24: ='INTERNAL BUDGET'!M48 -> 127 | G24: ='INTERNAL BUDGET'!N48 -> 127 | H24: ='INTERNAL BUDGET'!O48 -> 127 | I24: ='INTERNAL BUDGET'!P48 -> 127 | ... M24: ='INTERNAL BUDGET'!T48 -> 127 | N24: =SUM(B24:M24) -> 1524 | P24: 62.5 | S24: 62.5 | T24: 2
A25: PM Program / Support | B25: ='INTERNAL BUDGET'!I49 -> 0 | C25: ='INTERNAL BUDGET'!J49 -> 0 | D25: ='INTERNAL BUDGET'!K49 -> 0 | E25: ='INTERNAL BUDGET'!L49 -> 0 | F25: ='INTERNAL BUDGET'!M49 -> 0 | G25: ='INTERNAL BUDGET'!N49 -> 0 | H25: ='INTERNAL BUDGET'!O49 -> 0 | I25: ='INTERNAL BUDGET'!P49 -> 0 | ... M25: ='INTERNAL BUDGET'!T49 -> 0 | N25: =SUM(B25:M25) -> 0 | P25: 86 | S25: 100 | T25: 0
A27: Payroll Tax & Insurance | B27: ='INTERNAL BUDGET'!I19 -> 3778.808 | C27: ='INTERNAL BUDGET'!J19 -> 3435.28 | D27: ='INTERNAL BUDGET'!K19 -> 3778.808 | E27: ='INTERNAL BUDGET'!L19 -> 3778.808 | F27: ='INTERNAL BUDGET'!M19 -> 3607.044 | G27: ='INTERNAL BUDGET'!N19 -> 3778.808 | H27: ='INTERNAL BUDGET'!O19 -> 3950.572 | I27: ='INTERNAL BUDGET'!P19 -> 3607.044 | ... M27: ='INTERNAL BUDGET'!T19 -> 4143.9744 | N27: =SUM(B27:M27) -> 45570.378 | P27: 0.23 | S27: 0.23
A28: Direct Cost - Sub Total | B28: ='INTERNAL BUDGET'!I55 -> 27506.137 | C28: ='INTERNAL BUDGET'!J55 -> 24183.769 | D28: ='INTERNAL BUDGET'!K55 -> 26287.137 | E28: ='INTERNAL BUDGET'!L55 -> 26287.137 | F28: ='INTERNAL BUDGET'!M55 -> 25235.453 | G28: ='INTERNAL BUDGET'!N55 -> 26287.137 | H28: ='INTERNAL BUDGET'!O55 -> 27338.821 | I28: ='INTERNAL BUDGET'!P55 -> 25235.453 | ... M28: ='INTERNAL BUDGET'!T55 -> 28533.184 | N28: =SUM(B28:M28) -> 318079.33
A29: Overhead / Management | B29: ='INTERNAL BUDGET'!I57 -> 825.18412 | C29: ='INTERNAL BUDGET'!J57 -> 725.51308 | D29: ='INTERNAL BUDGET'!K57 -> 788.61412 | E29: ='INTERNAL BUDGET'!L57 -> 788.61412 | F29: ='INTERNAL BUDGET'!M57 -> 757.0636 | G29: ='INTERNAL BUDGET'!N57 -> 788.61412 | H29: ='INTERNAL BUDGET'!O57 -> 820.16464 | I29: ='INTERNAL BUDGET'!P57 -> 757.0636 | ... M29: ='INTERNAL BUDGET'!T57 -> 855.99551 | N29: =SUM(B29:M29) -> 9542.3799 | O29: # | P29: 0.03 | S29: 0.03
A30: Subtotal | B30: =SUM(B28:B29) -> 28331.321 | C30: =SUM(C28:C29) -> 24909.282 | D30: =SUM(D28:D29) -> 27075.751 | E30: =SUM(E28:E29) -> 27075.751 | F30: =SUM(F28:F29) -> 25992.517 | G30: =SUM(G28:G29) -> 27075.751 | H30: =SUM(H28:H29) -> 28158.986 | I30: =SUM(I28:I29) -> 25992.517 | ... M30: =SUM(M28:M29) -> 29389.179 | N30: =SUM(B30:M30) -> 327621.71
A31: Gross receipts tax | B31: =SUM('INTERNAL BUDGET'!I64) -> 39.66385 | C31: =SUM('INTERNAL BUDGET'!J64) -> 34.872995 | D31: =SUM('INTERNAL BUDGET'!K64) -> 37.906052 | E31: =SUM('INTERNAL BUDGET'!L64) -> 37.906052 | F31: =SUM('INTERNAL BUDGET'!M64) -> 36.389524 | G31: =SUM('INTERNAL BUDGET'!N64) -> 37.906052 | H31: =SUM('INTERNAL BUDGET'!O64) -> 39.42258 | I31: =SUM('INTERNAL BUDGET'!P64) -> 36.389524 | ... M31: =SUM('INTERNAL BUDGET'!T64) -> 41.144851 | N31: =SUM(B31:M31) -> 458.67039 | P31: 0.00765 | S31: 0.00765 | T31: Tier 3-4 ( $2.5M - $25M )
A32: TOTAL MONTHLY COST | B32: =SUM(B30:B31) -> 28370.985 | C32: =SUM(C30:C31) -> 24944.155 | D32: =SUM(D30:D31) -> 27113.657 | E32: =SUM(E30:E31) -> 27113.657 | F32: =SUM(F30:F31) -> 26028.906 | G32: =SUM(G30:G31) -> 27113.657 | H32: =SUM(H30:H31) -> 28198.409 | I32: =SUM(I30:I31) -> 26028.906 | ... M32: =SUM(M30:M31) -> 29430.324 | N32: =SUM(B32:M32) -> 328080.38 | O32: #
A34: NOTES:
A35: 0. This cost estimate is provided for budgeting and planning purposes only and does not constitute a binding agreement or guarantee of pricing. Final scope, pricing, and terms are subject to execution of a mutually agreed-upon written contract. This estimate is valid for thirty (30) days from the date issued unless otherwise stated in writing.
A36: 1. Vacation, sick leave, holidays, and other paid time off (PTO) requiring replacement coverage will be billed as incurred with prior client approval. All PTO accruals, including holiday pay for part-time personnel, remain the financial responsibility of the client, regardless of whether replacement coverage is required..
A37: 2. Estimated hours reflect part-time employment. Full-time employment is defined as 2,088 hours annually. Actual hours worked may vary. Overtime is not included and will be billed as incurred with approval or as outlined in the final contract.
A38: 3. All applicable personnel and payroll-related cost factors will be passed through to the client, including employee wages, payroll taxes, insurance, and employee benefit plans.
A39: 4. Mileage, supplies, and other reimbursable costs will be billed as incurred. Purchased materials will be re-billed at cost plus fifteen percent (15%) or a minimum fee of $50.00, whichever is greater.
A40: 5. Bonuses are not included in this estimate. A 401(k) benefit has been included as an employee benefit and is reflected in applicable labor cost factors.
A41: 6. Costs associated with the preventative maintenance platform will be billed only if requested and implemented.
A42: 7. In the event of any discrepancy, the terms of the final executed agreement shall govern
B50: =SUM(B32/B7) -> 161.19878
B52: =SUM(B14/B7) -> 15.227273
B53: =SUM(B15/B7) -> 14.54
B54: =SUM(B16/B7) -> 2.1
B56: =SUM(B50-$B$52-$B$53-$B$55) -> 131.43151 | C56: without union benfits
...

Sheet INTERNAL BUDGET
A1: !THIS IS FOR INTERNAL USE ONLY!
B2: CLIENT | I2: 2025
C3: Cost | D3: Inc Sep 1 2026 | E3: Markup | I3: Jan | J3: Feb | K3: March | L3: April | M3: May | N3: June | O3: July | P3: August | Q3: September | R3: October | S3: November | T3: December | W3: 2025
B4: Hours Per Month | I4: 176 | J4: 160 | K4: 176 | L4: 176 | M4: 168 | N4: 176 | O4: 184 | P4: 168 | Q4: 176 | R4: 176 | S4: 168 | T4: 184 | V4: Total Hours | W4: =SUM(I4:T4) -> 2088 | Z4: September | AA4: October | AB4: November | AC4: December
B5: Rate | C5: 93.35 | D5: 97.92 | I5: =$C$5 -> 93.35 | J5: =$C$5 -> 93.35 | K5: =$C$5 -> 93.35 | L5: =$C$5 -> 93.35 | M5: =$C$5 -> 93.35 | N5: =$C$5 -> 93.35 | O5: =$C$5 -> 93.35 | P5: =$C$5 -> 93.35 | Q5: =$D$5 -> 97.92 | R5: =$D$5 -> 97.92 | S5: =$D$5 -> 97.92 | T5: =$D$5 -> 97.92
G6: Labor Cost | I6: =I5*I4 -> 16429.6 | J6: =J5*J4 -> 14936 | K6: =K5*K4 -> 16429.6 | L6: =L5*L4 -> 16429.6 | M6: =M5*M4 -> 15682.8 | N6: =N5*N4 -> 16429.6 | O6: =O5*O4 -> 17176.4 | P6: =P5*P4 -> 15682.8 | ... T6: =T5*T4 -> 18017.28 | V6: Total Labor Cost | W6: =SUM(I6:T6) -> 198132.08
B8: Payroll Costs | C8: =SUM(C9:C15) -> 0.16542
B9: FICA - SSA (6.2% of Payroll) | C9: 0.06201
B10: FICA - Medicare (1.45% of Payroll) | C10: 0.0145
B11: FUTA - Unemployment | C11: 0.006
B12: CA - Unemployment | C12: 0.034
B13: CA - ETT (Employee training Tax) | C13: 0.00101
B14: WC Policy | C14: 0.0379
B15: Bonding Liability Insurance | C15: 0.01
B16: Profit mark-up Tax and insurance | C16: =(I19-I18)/I19 -> 0.28078261
E17: 0.23
G18: Total Payroll Costs | I18: =(I6*$C$8) -> 2717.7844 | J18: =(J6*$C$8) -> 2470.7131 | K18: =(K6*$C$8) -> 2717.7844 | L18: =(L6*$C$8) -> 2717.7844 | M18: =(M6*$C$8) -> 2594.2488 | N18: =(N6*$C$8) -> 2717.7844 | O18: =(O6*$C$8) -> 2841.3201 | P18: =(P6*$C$8) -> 2594.2488 | ... T18: =(T6*$C$8) -> 2980.4185 | V18: Total Payroll Costs | W18: =SUM(I18:T18) -> 32775.009
G19: Billable Tax and Insurance | I19: =I6*$E$17 -> 3778.808 | J19: =J6*$E$17 -> 3435.28 | K19: =K6*$E$17 -> 3778.808 | L19: =L6*$E$17 -> 3778.808 | M19: =M6*$E$17 -> 3607.044 | N19: =N6*$E$17 -> 3778.808 | O19: =O6*$E$17 -> 3950.572 | P19: =P6*$E$17 -> 3607.044 | ... T19: =T6*$E$17 -> 4143.9744 | V19: Total Payroll Revenue | W19: =SUM(I19:T19) -> 45570.378
V20: % of Payroll | W20: =AVERAGE(I21:T21) -> 0.16542
G21: % of Payroll | I21: =I18/I6 -> 0.16542 | J21: =J18/J6 -> 0.16542 | K21: =K18/K6 -> 0.16542 | L21: =L18/L6 -> 0.16542 | M21: =M18/M6 -> 0.16542 | N21: =N18/N6 -> 0.16542 | O21: =O18/O6 -> 0.16542 | P21: =P18/P6 -> 0.16542 | ... T21: =T18/T6 -> 0.16542
B22: Other Costs (per EE per Month) Union | D22: Increase Sept 1
B23: Union Health and Welfare employee | C23: 2680 | I23: =$C$23 -> 2680 | J23: =$C$23 -> 2680 | K23: =$C$23 -> 2680 | L23: =$C$23 -> 2680 | M23: =$C$23 -> 2680 | N23: =$C$23 -> 2680 | O23: =$C$23 -> 2680 | P23: =$C$23 -> 2680 | ... T23: =$C$23 -> 2680 | V23: Heath and Welfare | W23: =SUM(I23:T23) -> 32160
B24: Pension | C24: 14.54 | D24: 15.41 | I24: =$C$24*I4 -> 2559.04 | J24: =$C$24*J4 -> 2326.4 | K24: =$C$24*K4 -> 2559.04 | L24: =$C$24*L4 -> 2559.04 | M24: =$C$24*M4 -> 2442.72 | N24: =$C$24*N4 -> 2559.04 | O24: =$C$24*O4 -> 2675.36 | P24: =$C$24*P4 -> 2442.72 | Q24: =$D$24*Q4 -> 2712.16 | R24: =$D$24*R4 -> 2712.16 | S24: =$D$24*S4 -> 2588.88 | T24: =$D$24*T4 -> 2835.44 | V24: Pension | W24: =SUM(I24:T24) -> 30972
B25: Annuity | C25: 2.1 | D25: 2.1 | I25: =$C$25*I4 -> 369.6 | J25: =$C$25*J4 -> 336 | K25: =$C$25*K4 -> 369.6 | L25: =$C$25*L4 -> 369.6 | M25: =$C$25*M4 -> 352.8 | N25: =$C$25*N4 -> 369.6 | O25: =$C$25*O4 -> 386.4 | P25: =$C$25*P4 -> 352.8 | Q25: =$D$25*Q4 -> 369.6 | R25: =$D$25*R4 -> 369.6 | S25: =$D$25*S4 -> 352.8 | T25: =$D$25*T4 -> 386.4 | V25: Annuity | W25: =SUM(I25:T25) -> 4384.8
B26: Apprentiship Training Fund | C26: 1115 | I26: 1115 | V26: Local 39 Training Fund | W26: =SUM(I26:T26) -> 1115
B27: National Training Fund | C27: 104 | I27: 104 | V27: National Training Fund | W27: =SUM(I27:T27) -> 104
I28: =$C$28 | J28: =$C$28 | K28: =$C$28 | L28: =$C$28 | M28: =$C$28 | N28: =$C$28 | O28: =$C$28 | P28: =$C$28 | ... T28: =$C$28
B29: Health and Welfare Profit Markup
G30: Total Union Benefits | I30: =SUM(I23:I27)+$E$29 -> 6827.64 | J30: =SUM(J23:J27)+$E$29 -> 5342.4 | K30: =SUM(K23:K27)+$E$29 -> 5608.64 | L30: =SUM(L23:L27)+$E$29 -> 5608.64 | M30: =SUM(M23:M27)+$E$29 -> 5475.52 | N30: =SUM(N23:N27)+$E$29 -> 5608.64 | O30: =SUM(O23:O27)+$E$29 -> 5741.76 | P30: =SUM(P23:P27)+$E$29 -> 5475.52 | ... T30: =SUM(T23:T27)+$E$29 -> 5901.84 | V30: Total Union Benefits Revenue | W30: =SUM(W23:W28) -> 68735.8
B31: Cost to outfit maintence vehicle | W31: =SUM(I31:T31) -> 0
B32: (loan) (purchased) Cost of Maintence vehicle | W32: =SUM(I32:T32) -> 0
B33: Gas
B34: Miantenance
B36: Total Car | G36: Vehical cost | I36: =SUM(I31:I35) -> 0 | J36: =SUM(J31:J35) -> 0 | K36: =SUM(K31:K35) -> 0 | L36: =SUM(L31:L35) -> 0 | M36: =SUM(M31:M35) -> 0 | N36: =SUM(N31:N35) -> 0 | O36: =SUM(O31:O35) -> 0 | P36: =SUM(P31:P35) -> 0 | ... T36: =SUM(T31:T35) -> 0 | V36: Vehicle total cost | W36: =SUM(I36:T36) -> 0
B38: 401K @3.7% Salary Match | C38: 0.037 | G38: 401K @3.7% Salary Match | V38: 401K @3.7% Salary Match | W38: =SUM(I38:T38) -> 0
B40: Uniforms | C40: 154.5 | E40: 0.0194 | I40: =$C$40*(1+$E$40) -> 157.4973 | J40: =$C$40*(1+$E$40) -> 157.4973 | K40: =$C$40*(1+$E$40) -> 157.4973 | L40: =$C$40*(1+$E$40) -> 157.4973 | M40: =$C$40*(1+$E$40) -> 157.4973 | N40: =$C$40*(1+$E$40) -> 157.4973 | O40: =$C$40*(1+$E$40) -> 157.4973 | P40: =$C$40*(1+$E$40) -> 157.4973 | ... T40: =$C$40*(1+$E$40) -> 157.4973 | V40: Total Uniforms | W40: =SUM(I40:T40) -> 1889.9676
B41: Electronic Device | C41: 90 | E41: 0.05 | I41: =$C$41*(1+$E$41) -> 94.5 | J41: =$C$41*(1+$E$41) -> 94.5 | K41: =$C$41*(1+$E$41) -> 94.5 | L41: =$C$41*(1+$E$41) -> 94.5 | M41: =$C$41*(1+$E$41) -> 94.5 | N41: =$C$41*(1+$E$41) -> 94.5 | O41: =$C$41*(1+$E$41) -> 94.5 | P41: =$C$41*(1+$E$41) -> 94.5 | ... T41: =$C$41*(1+$E$41) -> 94.5 | V41: Total Electronic Device | W41: =SUM(I41:T41) -> 1134
B42: HR per person | C42: 59.52
B43: LIFE/LTD @50,001 | C43: 16.39
B44: HR & LIFE/LTD @50,000 | C44: =SUM(C42:C43) -> 75.91 | E44: 0.2 | I44: =$C$44*(1+$E$44) -> 91.092 | J44: =$C$44*(1+$E$44) -> 91.092 | K44: =$C$44*(1+$E$44) -> 91.092 | L44: =$C$44*(1+$E$44) -> 91.092 | M44: =$C$44*(1+$E$44) -> 91.092 | N44: =$C$44*(1+$E$44) -> 91.092 | O44: =$C$44*(1+$E$44) -> 91.092 | P44: =$C$44*(1+$E$44) -> 91.092 | ... T44: =$C$44*(1+$E$44) -> 91.092 | V44: Total LIFE/LTD @50,000 | W44: =SUM(I44:T44) -> 1093.104
...

Sheet loaded rate calc
A1: !THIS IS FOR INTERNAL USE ONLY!
B2: CLIENT | I2: 2025
C3: Cost | D3: Increase Sep 1 | E3: Markup | I3: April | J3: May | K3: June | L3: July | M3: August | N3: September | O3: October | P3: November | Q3: December | R3: January | S3: Feburary | T3: March | W3: 2025
B4: Hours Per Month | I4: 1 | J4: 176 | K4: 168 | L4: 184 | M4: 168 | N4: 176 | O4: 184 | P4: 160 | Q4: 184 | R4: 176 | S4: 160 | T4: 176 | V4: Total Hours | W4: =SUM(I4:T4) -> 1913
B5: Rate | C5: 160.44 | D5: 84.15 | I5: =$C$5 -> 160.44 | J5: =$C$5 -> 160.44 | K5: =$C$5 -> 160.44 | L5: =$C$5 -> 160.44 | M5: =$C$5 -> 160.44 | N5: =$D$5 -> 84.15 | O5: =$D$5 -> 84.15 | P5: =$D$5 -> 84.15 | Q5: =$D$5 -> 84.15 | R5: =$D$5 -> 84.15 | S5: =$D$5 -> 84.15 | T5: =$D$5 -> 84.15
G6: Labor Cost | I6: =I5*I4 -> 160.44 | J6: =J5*J4 -> 28237.44 | K6: =K5*K4 -> 26953.92 | L6: =L5*L4 -> 29520.96 | M6: =M5*M4 -> 26953.92 | N6: =N5*N4 -> 14810.4 | O6: =O5*O4 -> 15483.6 | P6: =P5*P4 -> 13464 | ... T6: =T5*T4 -> 14810.4 | V6: Total Labor Cost | W6: =SUM(I6:T6) -> 214153.08
B8: Payroll Costs | C8: =SUM(C9:C15) -> 0.16542
B9: FICA - SSA (6.2% of Payroll) | C9: 0.06201
B10: FICA - Medicare (1.45% of Payroll) | C10: 0.0145
B11: FUTA - Unemployment | C11: 0.006
B12: CA - Unemployment | C12: 0.034
B13: CA - ETT (Employee training Tax) | C13: 0.00101
B14: WC Policy | C14: 0.0379
B15: Bonding Liability Insurance | C15: 0.01
B16: Profit mark-up Tax and insurance | C16: =(I19-I18)/I19 -> 0.28078261
E17: 0.23
G18: Total Payroll Costs | I18: =(I6*$C$8) -> 26.539985 | J18: =(J6*$C$8) -> 4671.0373 | K18: =(K6*$C$8) -> 4458.7174 | L18: =(L6*$C$8) -> 4883.3572 | M18: =(M6*$C$8) -> 4458.7174 | N18: =(N6*$C$8) -> 2449.9364 | O18: =(O6*$C$8) -> 2561.2971 | P18: =(P6*$C$8) -> 2227.2149 | ... T18: =(T6*$C$8) -> 2449.9364 | V18: Total Payroll Costs | W18: =SUM(I18:T18) -> 35425.202
G19: Billable Tax and Insurance | I19: =I6*$E$17 -> 36.9012 | J19: =J6*$E$17 -> 6494.6112 | K19: =K6*$E$17 -> 6199.4016 | L19: =L6*$E$17 -> 6789.8208 | M19: =M6*$E$17 -> 6199.4016 | N19: =N6*$E$17 -> 3406.392 | O19: =O6*$E$17 -> 3561.228 | P19: =P6*$E$17 -> 3096.72 | ... T19: =T6*$E$17 -> 3406.392 | V19: Total Payroll Revenue | W19: =SUM(I19:T19) -> 49255.208
V20: % of Payroll | W20: =AVERAGE(I21:T21) -> 0.16542
G21: % of Payroll | I21: =I18/I6 -> 0.16542 | J21: =J18/J6 -> 0.16542 | K21: =K18/K6 -> 0.16542 | L21: =L18/L6 -> 0.16542 | M21: =M18/M6 -> 0.16542 | N21: =N18/N6 -> 0.16542 | O21: =O18/O6 -> 0.16542 | P21: =P18/P6 -> 0.16542 | ... T21: =T18/T6 -> 0.16542
B22: Other Costs (per EE per Month) Union | D22: Increase Sept 1
B23: Union Health and Welfare employee | C23: 2480 | I23: 0 | J23: =$C$23 -> 2480 | K23: =$C$23 -> 2480 | L23: =$C$23 -> 2480 | M23: =$C$23 -> 2480 | N23: =$C$23 -> 2480 | O23: =$C$23 -> 2480 | P23: =$C$23 -> 2480 | Q23: =$C$23 -> 2480 | ... T23: =$C$23 -> 2480 | V23: Heath and Welfare | W23: =SUM(I23:T23) -> 27280
B24: Pension | C24: 13.72 | D24: 14.54 | I24: =$C$24*I4 -> 13.72 | J24: =$C$24*J4 -> 2414.72 | K24: =$C$24*K4 -> 2304.96 | L24: =$C$24*L4 -> 2524.48 | M24: =$C$24*M4 -> 2304.96 | N24: =$D$24*N4 -> 2559.04 | O24: =$D$24*O4 -> 2675.36 | P24: =$D$24*P4 -> 2326.4 | Q24: =$D$24*Q4 -> 2675.36 | R24: =$D$24*R4 -> 2559.04 | S24: =$D$24*S4 -> 2326.4 | T24: =$D$24*T4 -> 2559.04 | V24: Pension | W24: =SUM(I24:T24) -> 27243.48
B25: Annuity | C25: 2.05 | D25: 2.1 | I25: =$C$25*I4 -> 2.05 | J25: =$C$25*J4 -> 360.8 | K25: =$C$25*K4 -> 344.4 | L25: =$C$25*L4 -> 377.2 | M25: =$C$25*M4 -> 344.4 | N25: =$D$25*N4 -> 369.6 | O25: =$D$25*O4 -> 386.4 | P25: =$D$25*P4 -> 336 | Q25: =$D$25*Q4 -> 386.4 | R25: =$D$25*R4 -> 369.6 | S25: =$D$25*S4 -> 336 | T25: =$D$25*T4 -> 369.6 | V25: Annuity | W25: =SUM(I25:T25) -> 3982.45
B26: Apprentiship Training Fund | C26: 1115 | R26: =SUM(C26) -> 1115 | V26: Local 39 Training Fund | W26: =SUM(I26:T26) -> 1115
B27: National Training Fund | C27: 104 | R27: =SUM(C27) -> 104 | V27: National Training Fund | W27: =SUM(I27:T27) -> 104
I28: =$C$28 | J28: =$C$28 | K28: =$C$28 | L28: =$C$28 | M28: =$C$28 | N28: =$C$28 | O28: =$C$28 | P28: =$C$28 | ... T28: =$C$28
B29: Health and Welfare Profit Markup
G30: Total Union Benefits | I30: =SUM(I23:I27)+$E$29 -> 15.77 | J30: =SUM(J23:J27)+$E$29 -> 5255.52 | K30: =SUM(K23:K27)+$E$29 -> 5129.36 | L30: =SUM(L23:L27)+$E$29 -> 5381.68 | M30: =SUM(M23:M27)+$E$29 -> 5129.36 | N30: =SUM(N23:N27)+$E$29 -> 5408.64 | O30: =SUM(O23:O27)+$E$29 -> 5541.76 | P30: =SUM(P23:P27)+$E$29 -> 5142.4 | ... T30: =SUM(T23:T27)+$E$29 -> 5408.64 | V30: Total Union Benefits Revenue | W30: =SUM(W23:W28) -> 59724.93
B31: Cost to outfit maintence vehicle | I31: 0 | W31: =SUM(I31:T31) -> 0
B32: (loan) (purchased) Cost of Maintence vehicle | I32: 0 | J32: 1500 | K32: 1500 | L32: 1500 | M32: 1500 | N32: 1500 | O32: 1500 | P32: 1500 | Q32: 1500 | R32: 1500 | S32: 1500 | T32: 1500 | W32: =SUM(I32:T32) -> 16500
B33: Gas
B34: Miantenance
B36: Total Car | G36: Vehical cost | I36: =SUM(I31:I35) -> 0 | J36: =SUM(J31:J35) -> 1500 | K36: =SUM(K31:K35) -> 1500 | L36: =SUM(L31:L35) -> 1500 | M36: =SUM(M31:M35) -> 1500 | N36: =SUM(N31:N35) -> 1500 | O36: =SUM(O31:O35) -> 1500 | P36: =SUM(P31:P35) -> 1500 | ... T36: =SUM(T31:T35) -> 1500 | V36: Vehicle total cost | W36: =SUM(I36:T36) -> 16500
B38: 401K @3.7% Salary Match | C38: 0.037 | G38: 401K @3.7% Salary Match | V38: 401K @3.7% Salary Match | W38: =SUM(I38:T38) -> 0
B40: Uniforms | C40: 125 | E40: 0.2 | I40: 0 | J40: =$C$40*(1+$E$40) -> 150 | K40: =$C$40*(1+$E$40) -> 150 | L40: =$C$40*(1+$E$40) -> 150 | M40: =$C$40*(1+$E$40) -> 150 | N40: =$C$40*(1+$E$40) -> 150 | O40: =$C$40*(1+$E$40) -> 150 | P40: =$C$40*(1+$E$40) -> 150 | Q40: =$C$40*(1+$E$40) -> 150 | ... T40: =$C$40*(1+$E$40) -> 150 | V40: Total Uniforms | W40: =SUM(I40:T40) -> 1650
B41: Electronic Device | C41: 90 | E41: 0.05 | I41: 0 | J41: =$C$41*(1+$E$41) -> 94.5 | K41: =$C$41*(1+$E$41) -> 94.5 | L41: =$C$41*(1+$E$41) -> 94.5 | M41: =$C$41*(1+$E$41) -> 94.5 | N41: =$C$41*(1+$E$41) -> 94.5 | O41: =$C$41*(1+$E$41) -> 94.5 | P41: =$C$41*(1+$E$41) -> 94.5 | Q41: =$C$41*(1+$E$41) -> 94.5 | ... T41: =$C$41*(1+$E$41) -> 94.5 | V41: Total Electronic Device | W41: =SUM(I41:T41) -> 1039.5
B42: HR per person | C42: 59.52
B43: LIFE/LTD @50,001 | C43: 16.39
B44: HR & LIFE/LTD @50,000 | C44: =SUM(C42:C43) -> 75.91 | E44: 0.1 | I44: 0 | J44: =$C$44*(1+$E$44) -> 83.501 | K44: =$C$44*(1+$E$44) -> 83.501 | L44: =$C$44*(1+$E$44) -> 83.501 | M44: =$C$44*(1+$E$44) -> 83.501 | N44: =$C$44*(1+$E$44) -> 83.501 | O44: =$C$44*(1+$E$44) -> 83.501 | P44: =$C$44*(1+$E$44) -> 83.501 | Q44: =$C$44*(1+$E$44) -> 83.501 | ... T44: =$C$44*(1+$E$44) -> 83.501 | V44: Total LIFE/LTD @50,000 | W44: =SUM(I44:T44) -> 918.511
...
